[2025-04-07 10:15:26] [INFO] __main__: Старт программы
[2025-04-07 10:15:26] [INFO] __main__: Загружено 3 строк из базы
[2025-04-07 10:20:48] [INFO] __main__: Старт программы
[2025-04-07 10:20:48] [INFO] __main__: Загружено 3 строк из базы
[2025-04-07 10:20:48] [INFO] __main__: Выполнена предобработка данных
[2025-04-07 10:20:48] [INFO] __main__: Статистика исходных данных: 
          id column_1  column_2  column_3                     created_at
count   3.0        3       3.0       3.0                              3
unique  NaN        3       NaN       NaN                            NaN
top     NaN    test1       NaN       NaN                            NaN
freq    NaN        1       NaN       NaN                            NaN
mean    2.0      NaN      20.0       1.5  2025-04-05 17:09:15.856753920
min     1.0      NaN      10.0       0.5     2025-04-05 17:09:15.856754
25%     1.5      NaN      15.0       1.0  2025-04-05 17:09:15.856753920
50%     2.0      NaN      20.0       1.5  2025-04-05 17:09:15.856753920
75%     2.5      NaN      25.0       2.0  2025-04-05 17:09:15.856753920
max     3.0      NaN      30.0       2.5     2025-04-05 17:09:15.856754
std     1.0      NaN      10.0       1.0                            NaN
[2025-04-07 10:20:48] [INFO] __main__: Допустимые отклнения: 
 {'column_int': {'percent': 10}, 'column_float': {'percent': 5}, 'column_date': {'days': 3}, 'column_timestamp': {'minutes': 60}}
[2025-04-07 10:20:49] [INFO] __main__: :Работа завершена
[2025-04-07 11:01:08] [INFO] __main__: 123
[2025-04-07 11:01:46] [INFO] __main__: database data loaded
[2025-04-07 11:05:45] [INFO] __main__: database data loaded
[2025-04-07 11:10:54] [INFO] __main__: database data loaded
[2025-04-07 11:11:40] [INFO] __main__: database data loaded
[2025-04-07 11:11:40] [INFO] data_manager: Загрузка данных из базы
[2025-04-07 11:11:40] [ERROR] data_manager: Ошибка при загрузке данных
Traceback (most recent call last):
  File "C:\Users\skyli\PycharmProjects\synthetic_data_project\src\data_manager.py", line 33, in load_data
    df = pd.read_sql(query_raw_data, self.engine)
         ^^^^^^^^^^^^^^^^^^^^^^^^^^^^^^^^^^^^^^^^
  File "C:\Users\skyli\AppData\Local\Programs\Python\Python312\Lib\site-packages\pandas\io\sql.py", line 704, in read_sql
    with pandasSQL_builder(con) as pandas_sql:
         ^^^^^^^^^^^^^^^^^^^^^^
  File "C:\Users\skyli\AppData\Local\Programs\Python\Python312\Lib\site-packages\pandas\io\sql.py", line 906, in pandasSQL_builder
    return SQLDatabase(con, schema, need_transaction)
           ^^^^^^^^^^^^^^^^^^^^^^^^^^^^^^^^^^^^^^^^^^
  File "C:\Users\skyli\AppData\Local\Programs\Python\Python312\Lib\site-packages\pandas\io\sql.py", line 1636, in __init__
    con = self.exit_stack.enter_context(con.connect())
                                        ^^^^^^^^^^^^^
  File "C:\Users\skyli\AppData\Local\Programs\Python\Python312\Lib\site-packages\sqlalchemy\engine\base.py", line 3274, in connect
    return self._connection_cls(self)
           ^^^^^^^^^^^^^^^^^^^^^^^^^^
  File "C:\Users\skyli\AppData\Local\Programs\Python\Python312\Lib\site-packages\sqlalchemy\engine\base.py", line 146, in __init__
    self._dbapi_connection = engine.raw_connection()
                             ^^^^^^^^^^^^^^^^^^^^^^^
  File "C:\Users\skyli\AppData\Local\Programs\Python\Python312\Lib\site-packages\sqlalchemy\engine\base.py", line 3298, in raw_connection
    return self.pool.connect()
           ^^^^^^^^^^^^^^^^^^^
  File "C:\Users\skyli\AppData\Local\Programs\Python\Python312\Lib\site-packages\sqlalchemy\pool\base.py", line 449, in connect
    return _ConnectionFairy._checkout(self)
           ^^^^^^^^^^^^^^^^^^^^^^^^^^^^^^^^
  File "C:\Users\skyli\AppData\Local\Programs\Python\Python312\Lib\site-packages\sqlalchemy\pool\base.py", line 1264, in _checkout
    fairy = _ConnectionRecord.checkout(pool)
            ^^^^^^^^^^^^^^^^^^^^^^^^^^^^^^^^
  File "C:\Users\skyli\AppData\Local\Programs\Python\Python312\Lib\site-packages\sqlalchemy\pool\base.py", line 713, in checkout
    rec = pool._do_get()
          ^^^^^^^^^^^^^^
  File "C:\Users\skyli\AppData\Local\Programs\Python\Python312\Lib\site-packages\sqlalchemy\pool\impl.py", line 179, in _do_get
    with util.safe_reraise():
  File "C:\Users\skyli\AppData\Local\Programs\Python\Python312\Lib\site-packages\sqlalchemy\util\langhelpers.py", line 146, in __exit__
    raise exc_value.with_traceback(exc_tb)
  File "C:\Users\skyli\AppData\Local\Programs\Python\Python312\Lib\site-packages\sqlalchemy\pool\impl.py", line 177, in _do_get
    return self._create_connection()
           ^^^^^^^^^^^^^^^^^^^^^^^^^
  File "C:\Users\skyli\AppData\Local\Programs\Python\Python312\Lib\site-packages\sqlalchemy\pool\base.py", line 390, in _create_connection
    return _ConnectionRecord(self)
           ^^^^^^^^^^^^^^^^^^^^^^^
  File "C:\Users\skyli\AppData\Local\Programs\Python\Python312\Lib\site-packages\sqlalchemy\pool\base.py", line 675, in __init__
    self.__connect()
  File "C:\Users\skyli\AppData\Local\Programs\Python\Python312\Lib\site-packages\sqlalchemy\pool\base.py", line 901, in __connect
    with util.safe_reraise():
  File "C:\Users\skyli\AppData\Local\Programs\Python\Python312\Lib\site-packages\sqlalchemy\util\langhelpers.py", line 146, in __exit__
    raise exc_value.with_traceback(exc_tb)
  File "C:\Users\skyli\AppData\Local\Programs\Python\Python312\Lib\site-packages\sqlalchemy\pool\base.py", line 897, in __connect
    self.dbapi_connection = connection = pool._invoke_creator(self)
                                         ^^^^^^^^^^^^^^^^^^^^^^^^^^
  File "C:\Users\skyli\AppData\Local\Programs\Python\Python312\Lib\site-packages\sqlalchemy\engine\create.py", line 646, in connect
    return dialect.connect(*cargs, **cparams)
           ^^^^^^^^^^^^^^^^^^^^^^^^^^^^^^^^^^
  File "C:\Users\skyli\AppData\Local\Programs\Python\Python312\Lib\site-packages\sqlalchemy\engine\default.py", line 625, in connect
    return self.loaded_dbapi.connect(*cargs, **cparams)  # type: ignore[no-any-return]  # NOQA: E501
           ^^^^^^^^^^^^^^^^^^^^^^^^^^^^^^^^^^^^^^^^^^^^
  File "C:\Users\skyli\AppData\Local\Programs\Python\Python312\Lib\site-packages\psycopg2\__init__.py", line 122, in connect
    conn = _connect(dsn, connection_factory=connection_factory, **kwasync)
           ^^^^^^^^^^^^^^^^^^^^^^^^^^^^^^^^^^^^^^^^^^^^^^^^^^^^^^^^^^^^^^^
UnicodeDecodeError: 'utf-8' codec can't decode byte 0xc2 in position 61: invalid continuation byte
[2025-04-07 11:12:32] [INFO] __main__: database data loaded
[2025-04-07 11:12:32] [INFO] __main__: Подключение и загрузка данных из БД
[2025-04-07 11:12:32] [INFO] data_manager: Загрузка данных из базы
[2025-04-07 11:12:32] [ERROR] data_manager: Ошибка при загрузке данных
Traceback (most recent call last):
  File "C:\Users\skyli\PycharmProjects\synthetic_data_project\src\data_manager.py", line 33, in load_data
    df = pd.read_sql(query_raw_data, self.engine)
         ^^^^^^^^^^^^^^^^^^^^^^^^^^^^^^^^^^^^^^^^
  File "C:\Users\skyli\AppData\Local\Programs\Python\Python312\Lib\site-packages\pandas\io\sql.py", line 704, in read_sql
    with pandasSQL_builder(con) as pandas_sql:
         ^^^^^^^^^^^^^^^^^^^^^^
  File "C:\Users\skyli\AppData\Local\Programs\Python\Python312\Lib\site-packages\pandas\io\sql.py", line 906, in pandasSQL_builder
    return SQLDatabase(con, schema, need_transaction)
           ^^^^^^^^^^^^^^^^^^^^^^^^^^^^^^^^^^^^^^^^^^
  File "C:\Users\skyli\AppData\Local\Programs\Python\Python312\Lib\site-packages\pandas\io\sql.py", line 1636, in __init__
    con = self.exit_stack.enter_context(con.connect())
                                        ^^^^^^^^^^^^^
  File "C:\Users\skyli\AppData\Local\Programs\Python\Python312\Lib\site-packages\sqlalchemy\engine\base.py", line 3274, in connect
    return self._connection_cls(self)
           ^^^^^^^^^^^^^^^^^^^^^^^^^^
  File "C:\Users\skyli\AppData\Local\Programs\Python\Python312\Lib\site-packages\sqlalchemy\engine\base.py", line 146, in __init__
    self._dbapi_connection = engine.raw_connection()
                             ^^^^^^^^^^^^^^^^^^^^^^^
  File "C:\Users\skyli\AppData\Local\Programs\Python\Python312\Lib\site-packages\sqlalchemy\engine\base.py", line 3298, in raw_connection
    return self.pool.connect()
           ^^^^^^^^^^^^^^^^^^^
  File "C:\Users\skyli\AppData\Local\Programs\Python\Python312\Lib\site-packages\sqlalchemy\pool\base.py", line 449, in connect
    return _ConnectionFairy._checkout(self)
           ^^^^^^^^^^^^^^^^^^^^^^^^^^^^^^^^
  File "C:\Users\skyli\AppData\Local\Programs\Python\Python312\Lib\site-packages\sqlalchemy\pool\base.py", line 1264, in _checkout
    fairy = _ConnectionRecord.checkout(pool)
            ^^^^^^^^^^^^^^^^^^^^^^^^^^^^^^^^
  File "C:\Users\skyli\AppData\Local\Programs\Python\Python312\Lib\site-packages\sqlalchemy\pool\base.py", line 713, in checkout
    rec = pool._do_get()
          ^^^^^^^^^^^^^^
  File "C:\Users\skyli\AppData\Local\Programs\Python\Python312\Lib\site-packages\sqlalchemy\pool\impl.py", line 179, in _do_get
    with util.safe_reraise():
  File "C:\Users\skyli\AppData\Local\Programs\Python\Python312\Lib\site-packages\sqlalchemy\util\langhelpers.py", line 146, in __exit__
    raise exc_value.with_traceback(exc_tb)
  File "C:\Users\skyli\AppData\Local\Programs\Python\Python312\Lib\site-packages\sqlalchemy\pool\impl.py", line 177, in _do_get
    return self._create_connection()
           ^^^^^^^^^^^^^^^^^^^^^^^^^
  File "C:\Users\skyli\AppData\Local\Programs\Python\Python312\Lib\site-packages\sqlalchemy\pool\base.py", line 390, in _create_connection
    return _ConnectionRecord(self)
           ^^^^^^^^^^^^^^^^^^^^^^^
  File "C:\Users\skyli\AppData\Local\Programs\Python\Python312\Lib\site-packages\sqlalchemy\pool\base.py", line 675, in __init__
    self.__connect()
  File "C:\Users\skyli\AppData\Local\Programs\Python\Python312\Lib\site-packages\sqlalchemy\pool\base.py", line 901, in __connect
    with util.safe_reraise():
  File "C:\Users\skyli\AppData\Local\Programs\Python\Python312\Lib\site-packages\sqlalchemy\util\langhelpers.py", line 146, in __exit__
    raise exc_value.with_traceback(exc_tb)
  File "C:\Users\skyli\AppData\Local\Programs\Python\Python312\Lib\site-packages\sqlalchemy\pool\base.py", line 897, in __connect
    self.dbapi_connection = connection = pool._invoke_creator(self)
                                         ^^^^^^^^^^^^^^^^^^^^^^^^^^
  File "C:\Users\skyli\AppData\Local\Programs\Python\Python312\Lib\site-packages\sqlalchemy\engine\create.py", line 646, in connect
    return dialect.connect(*cargs, **cparams)
           ^^^^^^^^^^^^^^^^^^^^^^^^^^^^^^^^^^
  File "C:\Users\skyli\AppData\Local\Programs\Python\Python312\Lib\site-packages\sqlalchemy\engine\default.py", line 625, in connect
    return self.loaded_dbapi.connect(*cargs, **cparams)  # type: ignore[no-any-return]  # NOQA: E501
           ^^^^^^^^^^^^^^^^^^^^^^^^^^^^^^^^^^^^^^^^^^^^
  File "C:\Users\skyli\AppData\Local\Programs\Python\Python312\Lib\site-packages\psycopg2\__init__.py", line 122, in connect
    conn = _connect(dsn, connection_factory=connection_factory, **kwasync)
           ^^^^^^^^^^^^^^^^^^^^^^^^^^^^^^^^^^^^^^^^^^^^^^^^^^^^^^^^^^^^^^^
UnicodeDecodeError: 'utf-8' codec can't decode byte 0xc2 in position 61: invalid continuation byte
[2025-04-07 11:13:20] [INFO] __main__: database data loaded
[2025-04-07 11:13:20] [INFO] __main__: Подключение и загрузка данных из БД
[2025-04-07 11:13:21] [INFO] data_manager: Ошибка подключения: 'utf-8' codec can't decode byte 0xc2 in position 61: invalid continuation byte
[2025-04-07 11:13:21] [INFO] data_manager: Загрузка данных из базы
[2025-04-07 11:13:21] [ERROR] data_manager: Ошибка при загрузке данных
Traceback (most recent call last):
  File "C:\Users\skyli\PycharmProjects\synthetic_data_project\src\data_manager.py", line 33, in load_data
    df = pd.read_sql(query_raw_data, self.engine)
         ^^^^^^^^^^^^^^^^^^^^^^^^^^^^^^^^^^^^^^^^
  File "C:\Users\skyli\AppData\Local\Programs\Python\Python312\Lib\site-packages\pandas\io\sql.py", line 704, in read_sql
    with pandasSQL_builder(con) as pandas_sql:
         ^^^^^^^^^^^^^^^^^^^^^^
  File "C:\Users\skyli\AppData\Local\Programs\Python\Python312\Lib\site-packages\pandas\io\sql.py", line 906, in pandasSQL_builder
    return SQLDatabase(con, schema, need_transaction)
           ^^^^^^^^^^^^^^^^^^^^^^^^^^^^^^^^^^^^^^^^^^
  File "C:\Users\skyli\AppData\Local\Programs\Python\Python312\Lib\site-packages\pandas\io\sql.py", line 1636, in __init__
    con = self.exit_stack.enter_context(con.connect())
                                        ^^^^^^^^^^^^^
  File "C:\Users\skyli\AppData\Local\Programs\Python\Python312\Lib\site-packages\sqlalchemy\engine\base.py", line 3274, in connect
    return self._connection_cls(self)
           ^^^^^^^^^^^^^^^^^^^^^^^^^^
  File "C:\Users\skyli\AppData\Local\Programs\Python\Python312\Lib\site-packages\sqlalchemy\engine\base.py", line 146, in __init__
    self._dbapi_connection = engine.raw_connection()
                             ^^^^^^^^^^^^^^^^^^^^^^^
  File "C:\Users\skyli\AppData\Local\Programs\Python\Python312\Lib\site-packages\sqlalchemy\engine\base.py", line 3298, in raw_connection
    return self.pool.connect()
           ^^^^^^^^^^^^^^^^^^^
  File "C:\Users\skyli\AppData\Local\Programs\Python\Python312\Lib\site-packages\sqlalchemy\pool\base.py", line 449, in connect
    return _ConnectionFairy._checkout(self)
           ^^^^^^^^^^^^^^^^^^^^^^^^^^^^^^^^
  File "C:\Users\skyli\AppData\Local\Programs\Python\Python312\Lib\site-packages\sqlalchemy\pool\base.py", line 1264, in _checkout
    fairy = _ConnectionRecord.checkout(pool)
            ^^^^^^^^^^^^^^^^^^^^^^^^^^^^^^^^
  File "C:\Users\skyli\AppData\Local\Programs\Python\Python312\Lib\site-packages\sqlalchemy\pool\base.py", line 713, in checkout
    rec = pool._do_get()
          ^^^^^^^^^^^^^^
  File "C:\Users\skyli\AppData\Local\Programs\Python\Python312\Lib\site-packages\sqlalchemy\pool\impl.py", line 179, in _do_get
    with util.safe_reraise():
  File "C:\Users\skyli\AppData\Local\Programs\Python\Python312\Lib\site-packages\sqlalchemy\util\langhelpers.py", line 146, in __exit__
    raise exc_value.with_traceback(exc_tb)
  File "C:\Users\skyli\AppData\Local\Programs\Python\Python312\Lib\site-packages\sqlalchemy\pool\impl.py", line 177, in _do_get
    return self._create_connection()
           ^^^^^^^^^^^^^^^^^^^^^^^^^
  File "C:\Users\skyli\AppData\Local\Programs\Python\Python312\Lib\site-packages\sqlalchemy\pool\base.py", line 390, in _create_connection
    return _ConnectionRecord(self)
           ^^^^^^^^^^^^^^^^^^^^^^^
  File "C:\Users\skyli\AppData\Local\Programs\Python\Python312\Lib\site-packages\sqlalchemy\pool\base.py", line 675, in __init__
    self.__connect()
  File "C:\Users\skyli\AppData\Local\Programs\Python\Python312\Lib\site-packages\sqlalchemy\pool\base.py", line 901, in __connect
    with util.safe_reraise():
  File "C:\Users\skyli\AppData\Local\Programs\Python\Python312\Lib\site-packages\sqlalchemy\util\langhelpers.py", line 146, in __exit__
    raise exc_value.with_traceback(exc_tb)
  File "C:\Users\skyli\AppData\Local\Programs\Python\Python312\Lib\site-packages\sqlalchemy\pool\base.py", line 897, in __connect
    self.dbapi_connection = connection = pool._invoke_creator(self)
                                         ^^^^^^^^^^^^^^^^^^^^^^^^^^
  File "C:\Users\skyli\AppData\Local\Programs\Python\Python312\Lib\site-packages\sqlalchemy\engine\create.py", line 646, in connect
    return dialect.connect(*cargs, **cparams)
           ^^^^^^^^^^^^^^^^^^^^^^^^^^^^^^^^^^
  File "C:\Users\skyli\AppData\Local\Programs\Python\Python312\Lib\site-packages\sqlalchemy\engine\default.py", line 625, in connect
    return self.loaded_dbapi.connect(*cargs, **cparams)  # type: ignore[no-any-return]  # NOQA: E501
           ^^^^^^^^^^^^^^^^^^^^^^^^^^^^^^^^^^^^^^^^^^^^
  File "C:\Users\skyli\AppData\Local\Programs\Python\Python312\Lib\site-packages\psycopg2\__init__.py", line 122, in connect
    conn = _connect(dsn, connection_factory=connection_factory, **kwasync)
           ^^^^^^^^^^^^^^^^^^^^^^^^^^^^^^^^^^^^^^^^^^^^^^^^^^^^^^^^^^^^^^^
UnicodeDecodeError: 'utf-8' codec can't decode byte 0xc2 in position 61: invalid continuation byte
[2025-04-07 11:15:57] [INFO] __main__: database data loaded
[2025-04-07 11:15:57] [INFO] __main__: Подключение и загрузка данных из БД
[2025-04-07 11:15:57] [INFO] data_manager: Ошибка подключения: 'utf-8' codec can't decode byte 0xc2 in position 61: invalid continuation byte
[2025-04-07 11:15:57] [INFO] data_manager: Загрузка данных из базы
[2025-04-07 11:15:57] [ERROR] data_manager: Ошибка при загрузке данных
Traceback (most recent call last):
  File "C:\Users\skyli\PycharmProjects\synthetic_data_project\src\data_manager.py", line 33, in load_data
    df = pd.read_sql(query_raw_data, self.engine)
         ^^^^^^^^^^^^^^^^^^^^^^^^^^^^^^^^^^^^^^^^
  File "C:\Users\skyli\AppData\Local\Programs\Python\Python312\Lib\site-packages\pandas\io\sql.py", line 704, in read_sql
    with pandasSQL_builder(con) as pandas_sql:
         ^^^^^^^^^^^^^^^^^^^^^^
  File "C:\Users\skyli\AppData\Local\Programs\Python\Python312\Lib\site-packages\pandas\io\sql.py", line 906, in pandasSQL_builder
    return SQLDatabase(con, schema, need_transaction)
           ^^^^^^^^^^^^^^^^^^^^^^^^^^^^^^^^^^^^^^^^^^
  File "C:\Users\skyli\AppData\Local\Programs\Python\Python312\Lib\site-packages\pandas\io\sql.py", line 1636, in __init__
    con = self.exit_stack.enter_context(con.connect())
                                        ^^^^^^^^^^^^^
  File "C:\Users\skyli\AppData\Local\Programs\Python\Python312\Lib\site-packages\sqlalchemy\engine\base.py", line 3274, in connect
    return self._connection_cls(self)
           ^^^^^^^^^^^^^^^^^^^^^^^^^^
  File "C:\Users\skyli\AppData\Local\Programs\Python\Python312\Lib\site-packages\sqlalchemy\engine\base.py", line 146, in __init__
    self._dbapi_connection = engine.raw_connection()
                             ^^^^^^^^^^^^^^^^^^^^^^^
  File "C:\Users\skyli\AppData\Local\Programs\Python\Python312\Lib\site-packages\sqlalchemy\engine\base.py", line 3298, in raw_connection
    return self.pool.connect()
           ^^^^^^^^^^^^^^^^^^^
  File "C:\Users\skyli\AppData\Local\Programs\Python\Python312\Lib\site-packages\sqlalchemy\pool\base.py", line 449, in connect
    return _ConnectionFairy._checkout(self)
           ^^^^^^^^^^^^^^^^^^^^^^^^^^^^^^^^
  File "C:\Users\skyli\AppData\Local\Programs\Python\Python312\Lib\site-packages\sqlalchemy\pool\base.py", line 1264, in _checkout
    fairy = _ConnectionRecord.checkout(pool)
            ^^^^^^^^^^^^^^^^^^^^^^^^^^^^^^^^
  File "C:\Users\skyli\AppData\Local\Programs\Python\Python312\Lib\site-packages\sqlalchemy\pool\base.py", line 713, in checkout
    rec = pool._do_get()
          ^^^^^^^^^^^^^^
  File "C:\Users\skyli\AppData\Local\Programs\Python\Python312\Lib\site-packages\sqlalchemy\pool\impl.py", line 179, in _do_get
    with util.safe_reraise():
  File "C:\Users\skyli\AppData\Local\Programs\Python\Python312\Lib\site-packages\sqlalchemy\util\langhelpers.py", line 146, in __exit__
    raise exc_value.with_traceback(exc_tb)
  File "C:\Users\skyli\AppData\Local\Programs\Python\Python312\Lib\site-packages\sqlalchemy\pool\impl.py", line 177, in _do_get
    return self._create_connection()
           ^^^^^^^^^^^^^^^^^^^^^^^^^
  File "C:\Users\skyli\AppData\Local\Programs\Python\Python312\Lib\site-packages\sqlalchemy\pool\base.py", line 390, in _create_connection
    return _ConnectionRecord(self)
           ^^^^^^^^^^^^^^^^^^^^^^^
  File "C:\Users\skyli\AppData\Local\Programs\Python\Python312\Lib\site-packages\sqlalchemy\pool\base.py", line 675, in __init__
    self.__connect()
  File "C:\Users\skyli\AppData\Local\Programs\Python\Python312\Lib\site-packages\sqlalchemy\pool\base.py", line 901, in __connect
    with util.safe_reraise():
  File "C:\Users\skyli\AppData\Local\Programs\Python\Python312\Lib\site-packages\sqlalchemy\util\langhelpers.py", line 146, in __exit__
    raise exc_value.with_traceback(exc_tb)
  File "C:\Users\skyli\AppData\Local\Programs\Python\Python312\Lib\site-packages\sqlalchemy\pool\base.py", line 897, in __connect
    self.dbapi_connection = connection = pool._invoke_creator(self)
                                         ^^^^^^^^^^^^^^^^^^^^^^^^^^
  File "C:\Users\skyli\AppData\Local\Programs\Python\Python312\Lib\site-packages\sqlalchemy\engine\create.py", line 646, in connect
    return dialect.connect(*cargs, **cparams)
           ^^^^^^^^^^^^^^^^^^^^^^^^^^^^^^^^^^
  File "C:\Users\skyli\AppData\Local\Programs\Python\Python312\Lib\site-packages\sqlalchemy\engine\default.py", line 625, in connect
    return self.loaded_dbapi.connect(*cargs, **cparams)  # type: ignore[no-any-return]  # NOQA: E501
           ^^^^^^^^^^^^^^^^^^^^^^^^^^^^^^^^^^^^^^^^^^^^
  File "C:\Users\skyli\AppData\Local\Programs\Python\Python312\Lib\site-packages\psycopg2\__init__.py", line 122, in connect
    conn = _connect(dsn, connection_factory=connection_factory, **kwasync)
           ^^^^^^^^^^^^^^^^^^^^^^^^^^^^^^^^^^^^^^^^^^^^^^^^^^^^^^^^^^^^^^^
UnicodeDecodeError: 'utf-8' codec can't decode byte 0xc2 in position 61: invalid continuation byte
